<?xml version="1.0" ?>
<!-- =================================================================================== -->
<!-- |    This document was autogenerated by xacro from phantomx.xacro                 | -->
<!-- |    EDITING THIS FILE BY HAND IS NOT RECOMMENDED                                 | -->
<!-- =================================================================================== -->
<robot name="PhantomX">
  <link name="base_link"/>
  <joint name="j_phantomx_attachment" type="fixed">
    <parent link="base_link"/>
    <child link="MP_BODY"/>
    <insert_block name="origin"/>
  </joint>
  <link name="MP_BODY">
    <inertial>
      <!-- <origin xyz="0 0 0" /> -->
      <mass value="0.97559947"/>
      <inertia ixx="3.1081800" ixy="-0.25460189" ixz="2.0318174" iyy="6.3787776" iyz="0.16417863" izz="5.3316425"/>
    </inertial>
    <visual>
      <!--origin xyz="-0.0235 0 -0.03525" rpy="0 0 0" /-->
      <origin rpy="0 0 0" xyz="0 0 0"/>
      <geometry>
        <!--box size="0.102 0.109 0.106" /-->
        <mesh filename="package://ros_gz_example_description/models/phantomx/meshes/body.STL" scale="1 1 1"/>
      </geometry>
      <material name="Grey">
        <color rgba="0.20 0.20 0.20 1.0"/>
      </material>
    </visual>
    <collision>
      <origin rpy="0 0 0" xyz="0 0 0"/>
      <geometry>
        <mesh filename="package://ros_gz_example_description/models/phantomx/meshes/body_coll.STL" scale="1 1 1"/>
      </geometry>
    </collision>
  </link>
  <gazebo reference="MP_BODY">
    <material>Gazebo/Grey</material>
  </gazebo>
  <link name="coxa1_rf">
    <inertial>
      <origin rpy="0 0 0" xyz="0 -0.02633 0"/>
      <mass value="0.04"/>
      <!-- <inertia ixx="0.0051411124"  ixy="-0.00057530255"  ixz="-0.000024729049" iyy="0.0081915737" iyz="-0.000019223094" izz="0.0011379812" /> -->
      <inertia ixx="1e-3" ixy="0.0" ixz="0.0" iyy="1e-3" iyz="0.0" izz="1e-3"/>
    </inertial>
    <visual>
      <origin rpy="0 0 0" xyz="0 -0.0252 0"/>
      <geometry>
        <!--box size="0.045 0.022 0.0325" /-->
        <mesh filename="package://ros_gz_example_description/models/phantomx/meshes/connect.STL" scale="1 1 1"/>
      </geometry>
      <material name="Grey">
        <color rgba="0.20 0.20 0.20 1.0"/>
      </material>
    </visual>
    <collision>
      <origin rpy="0 0 0" xyz="0 -0.02633 0"/>
      <geometry>
        <mesh filename="package://ros_gz_example_description/models/phantomx/meshes/connect_coll.STL" scale="1 1 1"/>
      </geometry>
    </collision>
  </link>
  <link name="coxa2_rf">
    <inertial>
      <origin rpy="0 0 0" xyz="0 -0.02633 0"/>
      <mass value="0.04"/>
      <!-- <inertia ixx="0.0051411124"  ixy="-0.00057530255"  ixz="-0.000024729049" iyy="0.0081915737" iyz="-0.000019223094" izz="0.0011379812" /> -->
      <inertia ixx="1e-3" ixy="0.0" ixz="0.0" iyy="1e-3" iyz="0.0" izz="1e-3"/>
    </inertial>
    <visual>
      <origin rpy="0 0 0" xyz="0 -0.0252 0"/>
      <geometry>
        <!--box size="0.045 0.022 0.0325" /-->
        <mesh filename="package://ros_gz_example_description/models/phantomx/meshes/connect.STL" scale="1 1 1"/>
      </geometry>
      <material name="Grey">
        <color rgba="0.20 0.20 0.20 1.0"/>
      </material>
    </visual>
    <collision>
      <origin rpy="0 0 0" xyz="0 -0.02633 0"/>
      <geometry>
        <mesh filename="package://ros_gz_example_description/models/phantomx/meshes/connect_coll.STL" scale="1 1 1"/>
      </geometry>
    </collision>
  </link>
  <link name="femur_rf">
    <inertial>
      <!-- <origin xyz="0 0 0" rpy="0 0 0"  /> -->
      <mass value="0.1"/>
      <!-- <inertia ixx="0.0051411124"  ixy="0"  ixz="0" iyy="0.0081915737" iyz="0" izz="0.0011379812" /> -->
      <!-- <inertia ixx="7.74*1e-4" ixy="0.0" ixz="0.0" iyy="3.52*1e-5" iyz="0.0" izz="8.39*1e-5"/> -->
      <inertia ixx="0.01" ixy="0.0" ixz="0.0" iyy="0.01" iyz="0.0" izz="0.01"/>
    </inertial>
    <visual>
      <origin rpy="0 0 0" xyz="0 0 0"/>
      <geometry>
        <!--box size="0.045 0.022 0.0325" /-->
        <mesh filename="package://ros_gz_example_description/models/phantomx/meshes/thigh_l.STL" scale="1 1 1"/>
      </geometry>
      <material name="Grey">
        <color rgba="0.20 0.20 0.20 1.0"/>
      </material>
    </visual>
    <collision>
      <origin rpy="0 0 0" xyz="0 0 0"/>
      <geometry>
        <mesh filename="package://ros_gz_example_description/models/phantomx/thigh_l_coll.STL" scale="1 1 1"/>
      </geometry>
    </collision>
  </link>
  <link name="tibia_rf">
    <inertial>
      <!-- <origin xyz="0 0 0" rpy="0 0 0"  /> -->
      <mass value="0.1"/>
      <!-- <inertia ixx="0.0051411124"  ixy="-0.00057530255"  ixz="-0.000024729049" iyy="0.0081915737" iyz="-0.000019223094" izz="0.0011379812" /> -->
      <!-- <inertia ixx="2.96*1e-3" ixy="0.0" ixz="0.0" iyy="2.74*1e-4" iyz="0.0" izz="6*1e-5"/> -->
      <inertia ixx="0.01" ixy="0.0" ixz="0.0" iyy="0.01" iyz="0.0" izz="0.01"/>
    </inertial>
    <visual>
      <origin rpy="0 0 0" xyz="0 0 0"/>
      <geometry>
        <!--box size="0.045 0.022 0.0325" /-->
        <mesh filename="package://ros_gz_example_description/models/phantomx/meshes/tibia_l.STL" scale="1 1 1"/>
      </geometry>
      <material name="Grey">
        <color rgba="0.20 0.20 0.20 1.0"/>
      </material>
    </visual>
    <collision>
      <origin rpy="0 0 0" xyz="0 0 0"/>
      <geometry>
        <mesh filename="package://ros_gz_example_description/models/phantomx/meshes/tibia_l_coll.STL" scale="1 1 1"/>
      </geometry>
    </collision>
  </link>
  <joint name="j_coxa1_rf" type="revolute">
    <parent link="MP_BODY"/>
    <child link="coxa1_rf"/>
    <origin rpy="0 4.7123 0.7853981633974483" xyz="0.1248 -0.06164  0.001116"/>
    <axis xyz="1 0 0"/>
    <limit effort="2.8" lower="-2.6179939" upper="2.6179939" velocity="5.6548668"/>
  </joint>
  <joint name="j_coxa2_rf" type="fixed">
    <parent link="coxa1_rf"/>
    <child link="coxa2_rf"/>
    <origin rpy="0 1.5704 3.14159" xyz="0 -0.054 0"/>
  </joint>
  <joint name="j_femur_rf" type="revolute">
    <parent link="coxa2_rf"/>
    <child link="femur_rf"/>
    <origin rpy=" 0 3.14159 3.14159" xyz="0 0 0"/>
    <axis xyz="1 0 0"/>
    <limit effort="2.8" lower="-2.6179939" upper="2.6179939" velocity="5.6548668"/>
  </joint>
  <joint name="j_tibia_rf" type="revolute">
    <parent link="femur_rf"/>
    <child link="tibia_rf"/>
    <origin rpy="-1.5707 0 3.14159" xyz="0 -0.0645 -0.0145"/>
    <axis xyz="1 0 0"/>
    <limit effort="2.8" lower="-2.6179939" upper="2.6179939" velocity="5.6548668"/>
  </joint>
  <transmission name="t_coxa1_rf">
    <type>transmission_interface/SimpleTransmission</type>
    <joint name="j_coxa1_rf">
      <hardwareInterface>EffortJointInterface</hardwareInterface>
    </joint>
    <actuator name="m_coxa1_rf">
      <hardwareInterface>EffortJointInterface</hardwareInterface>
      <mechanicalReduction>1</mechanicalReduction>
    </actuator>
  </transmission>
  <transmission name="t_femur_rf">
    <type>transmission_interface/SimpleTransmission</type>
    <joint name="j_femur_rf">
      <hardwareInterface>EffortJointInterface</hardwareInterface>
    </joint>
    <actuator name="m_femur_rf">
      <hardwareInterface>EffortJointInterface</hardwareInterface>
      <mechanicalReduction>1</mechanicalReduction>
    </actuator>
  </transmission>
  <transmission name="t_tibia_rf">
    <type>transmission_interface/SimpleTransmission</type>
    <joint name="j_tibia_rf">
      <hardwareInterface>EffortJointInterface</hardwareInterface>
    </joint>
    <actuator name="m_tibia_rf">
      <hardwareInterface>EffortJointInterface</hardwareInterface>
      <mechanicalReduction>1</mechanicalReduction>
    </actuator>
  </transmission>
  <gazebo reference="coxa1_rf">
    <material>Gazebo/Gray</material>
  </gazebo>
  <gazebo reference="coxa2_rf">
    <material>Gazebo/Gray</material>
  </gazebo>
  <gazebo reference="femur_rf">
    <material>Gazebo/Gray</material>
  </gazebo>
  <gazebo reference="femur_rf">
    <material>Gazebo/Gray</material>
  </gazebo>
  <link name="coxa1_rm">
    <inertial>
      <origin rpy="0 0 0" xyz="0 -0.02633 0"/>
      <mass value="0.04"/>
      <!-- <inertia ixx="0.0051411124"  ixy="-0.00057530255"  ixz="-0.000024729049" iyy="0.0081915737" iyz="-0.000019223094" izz="0.0011379812" /> -->
      <inertia ixx="1e-3" ixy="0.0" ixz="0.0" iyy="1e-3" iyz="0.0" izz="1e-3"/>
    </inertial>
    <visual>
      <origin rpy="0 0 0" xyz="0 -0.0252 0"/>
      <geometry>
        <!--box size="0.045 0.022 0.0325" /-->
        <mesh filename="package://ros_gz_example_description/models/phantomx/meshes/connect.STL" scale="1 1 1"/>
      </geometry>
      <material name="Grey">
        <color rgba="0.20 0.20 0.20 1.0"/>
      </material>
    </visual>
    <collision>
      <origin rpy="0 0 0" xyz="0 -0.02633 0"/>
      <geometry>
        <mesh filename="package://ros_gz_example_description/models/phantomx/meshes/connect_coll.STL" scale="1 1 1"/>
      </geometry>
    </collision>
  </link>
  <link name="coxa2_rm">
    <inertial>
      <origin rpy="0 0 0" xyz="0 -0.02633 0"/>
      <mass value="0.04"/>
      <!-- <inertia ixx="0.0051411124"  ixy="-0.00057530255"  ixz="-0.000024729049" iyy="0.0081915737" iyz="-0.000019223094" izz="0.0011379812" /> -->
      <inertia ixx="1e-3" ixy="0.0" ixz="0.0" iyy="1e-3" iyz="0.0" izz="1e-3"/>
    </inertial>
    <visual>
      <origin rpy="0 0 0" xyz="0 -0.0252 0"/>
      <geometry>
        <!--box size="0.045 0.022 0.0325" /-->
        <mesh filename="package://ros_gz_example_description/models/phantomx/meshes/connect.STL" scale="1 1 1"/>
      </geometry>
      <material name="Grey">
        <color rgba="0.20 0.20 0.20 1.0"/>
      </material>
    </visual>
    <collision>
      <origin rpy="0 0 0" xyz="0 -0.02633 0"/>
      <geometry>
        <mesh filename="package://ros_gz_example_description/models/phantomx/meshes/connect_coll.STL" scale="1 1 1"/>
      </geometry>
    </collision>
  </link>
  <link name="femur_rm">
    <inertial>
      <!-- <origin xyz="0 0 0" rpy="0 0 0"  /> -->
      <mass value="0.1"/>
      <!-- <inertia ixx="0.0051411124"  ixy="0"  ixz="0" iyy="0.0081915737" iyz="0" izz="0.0011379812" /> -->
      <!-- <inertia ixx="7.74*1e-4" ixy="0.0" ixz="0.0" iyy="3.52*1e-5" iyz="0.0" izz="8.39*1e-5"/> -->
      <inertia ixx="0.01" ixy="0.0" ixz="0.0" iyy="0.01" iyz="0.0" izz="0.01"/>
    </inertial>
    <visual>
      <origin rpy="0 0 0" xyz="0 0 0"/>
      <geometry>
        <!--box size="0.045 0.022 0.0325" /-->
        <mesh filename="package://ros_gz_example_description/models/phantomx/meshes/thigh_l.STL" scale="1 1 1"/>
      </geometry>
      <material name="Grey">
        <color rgba="0.20 0.20 0.20 1.0"/>
      </material>
    </visual>
    <collision>
      <origin rpy="0 0 0" xyz="0 0 0"/>
      <geometry>
        <mesh filename="package://ros_gz_example_description/models/phantomx/thigh_l_coll.STL" scale="1 1 1"/>
      </geometry>
    </collision>
  </link>
  <link name="tibia_rm">
    <inertial>
      <!-- <origin xyz="0 0 0" rpy="0 0 0"  /> -->
      <mass value="0.1"/>
      <!-- <inertia ixx="0.0051411124"  ixy="-0.00057530255"  ixz="-0.000024729049" iyy="0.0081915737" iyz="-0.000019223094" izz="0.0011379812" /> -->
      <!-- <inertia ixx="2.96*1e-3" ixy="0.0" ixz="0.0" iyy="2.74*1e-4" iyz="0.0" izz="6*1e-5"/> -->
      <inertia ixx="0.01" ixy="0.0" ixz="0.0" iyy="0.01" iyz="0.0" izz="0.01"/>
    </inertial>
    <visual>
      <origin rpy="0 0 0" xyz="0 0 0"/>
      <geometry>
        <!--box size="0.045 0.022 0.0325" /-->
        <mesh filename="package://ros_gz_example_description/models/phantomx/meshes/tibia_l.STL" scale="1 1 1"/>
      </geometry>
      <material name="Grey">
        <color rgba="0.20 0.20 0.20 1.0"/>
      </material>
    </visual>
    <collision>
      <origin rpy="0 0 0" xyz="0 0 0"/>
      <geometry>
        <mesh filename="package://ros_gz_example_description/models/phantomx/meshes/tibia_l_coll.STL" scale="1 1 1"/>
      </geometry>
    </collision>
  </link>
  <joint name="j_coxa1_rm" type="revolute">
    <parent link="MP_BODY"/>
    <child link="coxa1_rm"/>
    <origin rpy="0 4.7123 0" xyz="0 -0.1034  0.001116"/>
    <axis xyz="1 0 0"/>
    <limit effort="2.8" lower="-2.6179939" upper="2.6179939" velocity="5.6548668"/>
  </joint>
  <joint name="j_coxa2_rm" type="fixed">
    <parent link="coxa1_rm"/>
    <child link="coxa2_rm"/>
    <origin rpy="0 1.5704 3.14159" xyz="0 -0.054 0"/>
  </joint>
  <joint name="j_femur_rm" type="revolute">
    <parent link="coxa2_rm"/>
    <child link="femur_rm"/>
    <origin rpy=" 0 3.14159 3.14159" xyz="0 0 0"/>
    <axis xyz="1 0 0"/>
    <limit effort="2.8" lower="-2.6179939" upper="2.6179939" velocity="5.6548668"/>
  </joint>
  <joint name="j_tibia_rm" type="revolute">
    <parent link="femur_rm"/>
    <child link="tibia_rm"/>
    <origin rpy="-1.5707 0 3.14159" xyz="0 -0.0645 -0.0145"/>
    <axis xyz="1 0 0"/>
    <limit effort="2.8" lower="-2.6179939" upper="2.6179939" velocity="5.6548668"/>
  </joint>
  <transmission name="t_coxa1_rm">
    <type>transmission_interface/SimpleTransmission</type>
    <joint name="j_coxa1_rm">
      <hardwareInterface>EffortJointInterface</hardwareInterface>
    </joint>
    <actuator name="m_coxa1_rm">
      <hardwareInterface>EffortJointInterface</hardwareInterface>
      <mechanicalReduction>1</mechanicalReduction>
    </actuator>
  </transmission>
  <transmission name="t_femur_rm">
    <type>transmission_interface/SimpleTransmission</type>
    <joint name="j_femur_rm">
      <hardwareInterface>EffortJointInterface</hardwareInterface>
    </joint>
    <actuator name="m_femur_rm">
      <hardwareInterface>EffortJointInterface</hardwareInterface>
      <mechanicalReduction>1</mechanicalReduction>
    </actuator>
  </transmission>
  <transmission name="t_tibia_rm">
    <type>transmission_interface/SimpleTransmission</type>
    <joint name="j_tibia_rm">
      <hardwareInterface>EffortJointInterface</hardwareInterface>
    </joint>
    <actuator name="m_tibia_rm">
      <hardwareInterface>EffortJointInterface</hardwareInterface>
      <mechanicalReduction>1</mechanicalReduction>
    </actuator>
  </transmission>
  <gazebo reference="coxa1_rm">
    <material>Gazebo/Gray</material>
  </gazebo>
  <gazebo reference="coxa2_rm">
    <material>Gazebo/Gray</material>
  </gazebo>
  <gazebo reference="femur_rm">
    <material>Gazebo/Gray</material>
  </gazebo>
  <gazebo reference="femur_rm">
    <material>Gazebo/Gray</material>
  </gazebo>
  <link name="coxa1_rr">
    <inertial>
      <origin rpy="0 0 0" xyz="0 -0.02633 0"/>
      <mass value="0.04"/>
      <!-- <inertia ixx="0.0051411124"  ixy="-0.00057530255"  ixz="-0.000024729049" iyy="0.0081915737" iyz="-0.000019223094" izz="0.0011379812" /> -->
      <inertia ixx="1e-3" ixy="0.0" ixz="0.0" iyy="1e-3" iyz="0.0" izz="1e-3"/>
    </inertial>
    <visual>
      <origin rpy="0 0 0" xyz="0 -0.0252 0"/>
      <geometry>
        <!--box size="0.045 0.022 0.0325" /-->
        <mesh filename="package://ros_gz_example_description/models/phantomx/meshes/connect.STL" scale="1 1 1"/>
      </geometry>
      <material name="Grey">
        <color rgba="0.20 0.20 0.20 1.0"/>
      </material>
    </visual>
    <collision>
      <origin rpy="0 0 0" xyz="0 -0.02633 0"/>
      <geometry>
        <mesh filename="package://ros_gz_example_description/models/phantomx/meshes/connect_coll.STL" scale="1 1 1"/>
      </geometry>
    </collision>
  </link>
  <link name="coxa2_rr">
    <inertial>
      <origin rpy="0 0 0" xyz="0 -0.02633 0"/>
      <mass value="0.04"/>
      <!-- <inertia ixx="0.0051411124"  ixy="-0.00057530255"  ixz="-0.000024729049" iyy="0.0081915737" iyz="-0.000019223094" izz="0.0011379812" /> -->
      <inertia ixx="1e-3" ixy="0.0" ixz="0.0" iyy="1e-3" iyz="0.0" izz="1e-3"/>
    </inertial>
    <visual>
      <origin rpy="0 0 0" xyz="0 -0.0252 0"/>
      <geometry>
        <!--box size="0.045 0.022 0.0325" /-->
        <mesh filename="package://ros_gz_example_description/models/phantomx/meshes/connect.STL" scale="1 1 1"/>
      </geometry>
      <material name="Grey">
        <color rgba="0.20 0.20 0.20 1.0"/>
      </material>
    </visual>
    <collision>
      <origin rpy="0 0 0" xyz="0 -0.02633 0"/>
      <geometry>
        <mesh filename="package://ros_gz_example_description/models/phantomx/meshes/connect_coll.STL" scale="1 1 1"/>
      </geometry>
    </collision>
  </link>
  <link name="femur_rr">
    <inertial>
      <!-- <origin xyz="0 0 0" rpy="0 0 0"  /> -->
      <mass value="0.1"/>
      <!-- <inertia ixx="0.0051411124"  ixy="0"  ixz="0" iyy="0.0081915737" iyz="0" izz="0.0011379812" /> -->
      <!-- <inertia ixx="7.74*1e-4" ixy="0.0" ixz="0.0" iyy="3.52*1e-5" iyz="0.0" izz="8.39*1e-5"/> -->
      <inertia ixx="0.01" ixy="0.0" ixz="0.0" iyy="0.01" iyz="0.0" izz="0.01"/>
    </inertial>
    <visual>
      <origin rpy="0 0 0" xyz="0 0 0"/>
      <geometry>
        <!--box size="0.045 0.022 0.0325" /-->
        <mesh filename="package://ros_gz_example_description/models/phantomx/meshes/thigh_l.STL" scale="1 1 1"/>
      </geometry>
      <material name="Grey">
        <color rgba="0.20 0.20 0.20 1.0"/>
      </material>
    </visual>
    <collision>
      <origin rpy="0 0 0" xyz="0 0 0"/>
      <geometry>
        <mesh filename="package://ros_gz_example_description/models/phantomx/thigh_l_coll.STL" scale="1 1 1"/>
      </geometry>
    </collision>
  </link>
  <link name="tibia_rr">
    <inertial>
      <!-- <origin xyz="0 0 0" rpy="0 0 0"  /> -->
      <mass value="0.1"/>
      <!-- <inertia ixx="0.0051411124"  ixy="-0.00057530255"  ixz="-0.000024729049" iyy="0.0081915737" iyz="-0.000019223094" izz="0.0011379812" /> -->
      <!-- <inertia ixx="2.96*1e-3" ixy="0.0" ixz="0.0" iyy="2.74*1e-4" iyz="0.0" izz="6*1e-5"/> -->
      <inertia ixx="0.01" ixy="0.0" ixz="0.0" iyy="0.01" iyz="0.0" izz="0.01"/>
    </inertial>
    <visual>
      <origin rpy="0 0 0" xyz="0 0 0"/>
      <geometry>
        <!--box size="0.045 0.022 0.0325" /-->
        <mesh filename="package://ros_gz_example_description/models/phantomx/meshes/tibia_l.STL" scale="1 1 1"/>
      </geometry>
      <material name="Grey">
        <color rgba="0.20 0.20 0.20 1.0"/>
      </material>
    </visual>
    <collision>
      <origin rpy="0 0 0" xyz="0 0 0"/>
      <geometry>
        <mesh filename="package://ros_gz_example_description/models/phantomx/meshes/tibia_l_coll.STL" scale="1 1 1"/>
      </geometry>
    </collision>
  </link>
  <joint name="j_coxa1_rr" type="revolute">
    <parent link="MP_BODY"/>
    <child link="coxa1_rr"/>
    <origin rpy="0 4.7123 -0.7853981633974483" xyz="-0.1248 -0.06164  0.001116"/>
    <axis xyz="1 0 0"/>
    <limit effort="2.8" lower="-2.6179939" upper="2.6179939" velocity="5.6548668"/>
  </joint>
  <joint name="j_coxa2_rr" type="fixed">
    <parent link="coxa1_rr"/>
    <child link="coxa2_rr"/>
    <origin rpy="0 1.5704 3.14159" xyz="0 -0.054 0"/>
  </joint>
  <joint name="j_femur_rr" type="revolute">
    <parent link="coxa2_rr"/>
    <child link="femur_rr"/>
    <origin rpy=" 0 3.14159 3.14159" xyz="0 0 0"/>
    <axis xyz="1 0 0"/>
    <limit effort="2.8" lower="-2.6179939" upper="2.6179939" velocity="5.6548668"/>
  </joint>
  <joint name="j_tibia_rr" type="revolute">
    <parent link="femur_rr"/>
    <child link="tibia_rr"/>
    <origin rpy="-1.5707 0 3.14159" xyz="0 -0.0645 -0.0145"/>
    <axis xyz="1 0 0"/>
    <limit effort="2.8" lower="-2.6179939" upper="2.6179939" velocity="5.6548668"/>
  </joint>
  <transmission name="t_coxa1_rr">
    <type>transmission_interface/SimpleTransmission</type>
    <joint name="j_coxa1_rr">
      <hardwareInterface>EffortJointInterface</hardwareInterface>
    </joint>
    <actuator name="m_coxa1_rr">
      <hardwareInterface>EffortJointInterface</hardwareInterface>
      <mechanicalReduction>1</mechanicalReduction>
    </actuator>
  </transmission>
  <transmission name="t_femur_rr">
    <type>transmission_interface/SimpleTransmission</type>
    <joint name="j_femur_rr">
      <hardwareInterface>EffortJointInterface</hardwareInterface>
    </joint>
    <actuator name="m_femur_rr">
      <hardwareInterface>EffortJointInterface</hardwareInterface>
      <mechanicalReduction>1</mechanicalReduction>
    </actuator>
  </transmission>
  <transmission name="t_tibia_rr">
    <type>transmission_interface/SimpleTransmission</type>
    <joint name="j_tibia_rr">
      <hardwareInterface>EffortJointInterface</hardwareInterface>
    </joint>
    <actuator name="m_tibia_rr">
      <hardwareInterface>EffortJointInterface</hardwareInterface>
      <mechanicalReduction>1</mechanicalReduction>
    </actuator>
  </transmission>
  <gazebo reference="coxa1_rr">
    <material>Gazebo/Gray</material>
  </gazebo>
  <gazebo reference="coxa2_rr">
    <material>Gazebo/Gray</material>
  </gazebo>
  <gazebo reference="femur_rr">
    <material>Gazebo/Gray</material>
  </gazebo>
  <gazebo reference="femur_rr">
    <material>Gazebo/Gray</material>
  </gazebo>
  <link name="coxa1_lf">
    <inertial>
      <origin rpy="0 0 0" xyz="0 -0.02633 0"/>
      <mass value="0.04"/>
      <!-- <inertia ixx="0.0051411124"  ixy="-0.00057530255"  ixz="-0.000024729049" iyy="0.0081915737" iyz="-0.000019223094" izz="0.0011379812" /> -->
      <inertia ixx="1e-3" ixy="0.0" ixz="0.0" iyy="1e-3" iyz="0.0" izz="1e-3"/>
    </inertial>
    <visual>
      <origin rpy="0 0 0" xyz="0 -0.0252 0"/>
      <geometry>
        <!--box size="0.045 0.022 0.0325" /-->
        <mesh filename="package://ros_gz_example_description/models/phantomx/meshes/connect.STL" scale="1 1 1"/>
      </geometry>
      <material name="Grey">
        <color rgba="0.20 0.20 0.20 1.0"/>
      </material>
    </visual>
    <collision>
      <origin rpy="0 0 0" xyz="0 -0.02633 0"/>
      <geometry>
        <mesh filename="package://ros_gz_example_description/models/phantomx/meshes/connect_coll.STL" scale="1 1 1"/>
      </geometry>
    </collision>
  </link>
  <link name="coxa2_lf">
    <inertial>
      <origin rpy="0 0 0" xyz="0 -0.02633 0"/>
      <mass value="0.04"/>
      <!-- <inertia ixx="0.0051411124"  ixy="-0.00057530255"  ixz="-0.000024729049" iyy="0.0081915737" iyz="-0.000019223094" izz="0.0011379812" /> -->
      <inertia ixx="1e-3" ixy="0.0" ixz="0.0" iyy="1e-3" iyz="0.0" izz="1e-3"/>
    </inertial>
    <visual>
      <origin rpy="0 0 0" xyz="0 -0.0252 0"/>
      <geometry>
        <!--box size="0.045 0.022 0.0325" /-->
        <mesh filename="package://ros_gz_example_description/models/phantomx/meshes/connect.STL" scale="1 1 1"/>
      </geometry>
      <material name="Grey">
        <color rgba="0.20 0.20 0.20 1.0"/>
      </material>
    </visual>
    <collision>
      <origin rpy="0 0 0" xyz="0 -0.02633 0"/>
      <geometry>
        <mesh filename="package://ros_gz_example_description/models/phantomx/meshes/connect_coll.STL" scale="1 1 1"/>
      </geometry>
    </collision>
  </link>
  <link name="femur_lf">
    <inertial>
      <!-- <origin xyz="0 0 0" rpy="0 0 0"  /> -->
      <mass value="0.1"/>
      <!-- <inertia ixx="0.0051411124"  ixy="0"  ixz="0" iyy="0.0081915737" iyz="0" izz="0.0011379812" /> -->
      <!-- <inertia ixx="7.74*1e-4" ixy="0.0" ixz="0.0" iyy="3.52*1e-5" iyz="0.0" izz="8.39*1e-5"/> -->
      <inertia ixx="0.01" ixy="0.0" ixz="0.0" iyy="0.01" iyz="0.0" izz="0.01"/>
    </inertial>
    <visual>
      <origin rpy="0 0 0" xyz="0 0 0"/>
      <geometry>
        <!--box size="0.045 0.022 0.0325" /-->
        <mesh filename="package://ros_gz_example_description/models/phantomx/meshes/thigh_l.STL" scale="1 1 1"/>
      </geometry>
      <material name="Grey">
        <color rgba="0.20 0.20 0.20 1.0"/>
      </material>
    </visual>
    <collision>
      <origin rpy="0 0 0" xyz="0 0 0"/>
      <geometry>
        <mesh filename="package://ros_gz_example_description/models/phantomx/thigh_l_coll.STL" scale="1 1 1"/>
      </geometry>
    </collision>
  </link>
  <link name="tibia_lf">
    <inertial>
      <!-- <origin xyz="0 0 0" rpy="0 0 0"  /> -->
      <mass value="0.1"/>
      <!-- <inertia ixx="0.0051411124"  ixy="-0.00057530255"  ixz="-0.000024729049" iyy="0.0081915737" iyz="-0.000019223094" izz="0.0011379812" /> -->
      <!-- <inertia ixx="2.96*1e-3" ixy="0.0" ixz="0.0" iyy="2.74*1e-4" iyz="0.0" izz="6*1e-5"/> -->
      <inertia ixx="0.01" ixy="0.0" ixz="0.0" iyy="0.01" iyz="0.0" izz="0.01"/>
    </inertial>
    <visual>
      <origin rpy="0 0 0" xyz="0 0 0"/>
      <geometry>
        <!--box size="0.045 0.022 0.0325" /-->
        <mesh filename="package://ros_gz_example_description/models/phantomx/meshes/tibia_l.STL" scale="1 1 1"/>
      </geometry>
      <material name="Grey">
        <color rgba="0.20 0.20 0.20 1.0"/>
      </material>
    </visual>
    <collision>
      <origin rpy="0 0 0" xyz="0 0 0"/>
      <geometry>
        <mesh filename="package://ros_gz_example_description/models/phantomx/meshes/tibia_l_coll.STL" scale="1 1 1"/>
      </geometry>
    </collision>
  </link>
  <joint name="j_coxa1_lf" type="revolute">
    <parent link="MP_BODY"/>
    <child link="coxa1_lf"/>
    <origin rpy="0 4.7123 2.356194490192345" xyz="0.1248 0.06164  0.001116"/>
    <axis xyz="1 0 0"/>
    <limit effort="2.8" lower="-2.6179939" upper="2.6179939" velocity="5.6548668"/>
  </joint>
  <joint name="j_coxa2_lf" type="fixed">
    <parent link="coxa1_lf"/>
    <child link="coxa2_lf"/>
    <origin rpy="0 1.5704 3.14159" xyz="0 -0.054 0"/>
  </joint>
  <joint name="j_femur_lf" type="revolute">
    <parent link="coxa2_lf"/>
    <child link="femur_lf"/>
    <origin rpy=" 0 3.14159 3.14159" xyz="0 0 0"/>
    <axis xyz="1 0 0"/>
    <limit effort="2.8" lower="-2.6179939" upper="2.6179939" velocity="5.6548668"/>
  </joint>
  <joint name="j_tibia_lf" type="revolute">
    <parent link="femur_lf"/>
    <child link="tibia_lf"/>
    <origin rpy="-1.5707 0 3.14159" xyz="0 -0.0645 -0.0145"/>
    <axis xyz="1 0 0"/>
    <limit effort="2.8" lower="-2.6179939" upper="2.6179939" velocity="5.6548668"/>
  </joint>
  <transmission name="t_coxa1_lf">
    <type>transmission_interface/SimpleTransmission</type>
    <joint name="j_coxa1_lf">
      <hardwareInterface>EffortJointInterface</hardwareInterface>
    </joint>
    <actuator name="m_coxa1_lf">
      <hardwareInterface>EffortJointInterface</hardwareInterface>
      <mechanicalReduction>1</mechanicalReduction>
    </actuator>
  </transmission>
  <transmission name="t_femur_lf">
    <type>transmission_interface/SimpleTransmission</type>
    <joint name="j_femur_lf">
      <hardwareInterface>EffortJointInterface</hardwareInterface>
    </joint>
    <actuator name="m_femur_lf">
      <hardwareInterface>EffortJointInterface</hardwareInterface>
      <mechanicalReduction>1</mechanicalReduction>
    </actuator>
  </transmission>
  <transmission name="t_tibia_lf">
    <type>transmission_interface/SimpleTransmission</type>
    <joint name="j_tibia_lf">
      <hardwareInterface>EffortJointInterface</hardwareInterface>
    </joint>
    <actuator name="m_tibia_lf">
      <hardwareInterface>EffortJointInterface</hardwareInterface>
      <mechanicalReduction>1</mechanicalReduction>
    </actuator>
  </transmission>
  <gazebo reference="coxa1_lf">
    <material>Gazebo/Gray</material>
  </gazebo>
  <gazebo reference="coxa2_lf">
    <material>Gazebo/Gray</material>
  </gazebo>
  <gazebo reference="femur_lf">
    <material>Gazebo/Gray</material>
  </gazebo>
  <gazebo reference="femur_lf">
    <material>Gazebo/Gray</material>
  </gazebo>
  <link name="coxa1_lm">
    <inertial>
      <origin rpy="0 0 0" xyz="0 -0.02633 0"/>
      <mass value="0.04"/>
      <!-- <inertia ixx="0.0051411124"  ixy="-0.00057530255"  ixz="-0.000024729049" iyy="0.0081915737" iyz="-0.000019223094" izz="0.0011379812" /> -->
      <inertia ixx="1e-3" ixy="0.0" ixz="0.0" iyy="1e-3" iyz="0.0" izz="1e-3"/>
    </inertial>
    <visual>
      <origin rpy="0 0 0" xyz="0 -0.0252 0"/>
      <geometry>
        <!--box size="0.045 0.022 0.0325" /-->
        <mesh filename="package://ros_gz_example_description/models/phantomx/meshes/connect.STL" scale="1 1 1"/>
      </geometry>
      <material name="Grey">
        <color rgba="0.20 0.20 0.20 1.0"/>
      </material>
    </visual>
    <collision>
      <origin rpy="0 0 0" xyz="0 -0.02633 0"/>
      <geometry>
        <mesh filename="package://ros_gz_example_description/models/phantomx/meshes/connect_coll.STL" scale="1 1 1"/>
      </geometry>
    </collision>
  </link>
  <link name="coxa2_lm">
    <inertial>
      <origin rpy="0 0 0" xyz="0 -0.02633 0"/>
      <mass value="0.04"/>
      <!-- <inertia ixx="0.0051411124"  ixy="-0.00057530255"  ixz="-0.000024729049" iyy="0.0081915737" iyz="-0.000019223094" izz="0.0011379812" /> -->
      <inertia ixx="1e-3" ixy="0.0" ixz="0.0" iyy="1e-3" iyz="0.0" izz="1e-3"/>
    </inertial>
    <visual>
      <origin rpy="0 0 0" xyz="0 -0.0252 0"/>
      <geometry>
        <!--box size="0.045 0.022 0.0325" /-->
        <mesh filename="package://ros_gz_example_description/models/phantomx/meshes/connect.STL" scale="1 1 1"/>
      </geometry>
      <material name="Grey">
        <color rgba="0.20 0.20 0.20 1.0"/>
      </material>
    </visual>
    <collision>
      <origin rpy="0 0 0" xyz="0 -0.02633 0"/>
      <geometry>
        <mesh filename="package://ros_gz_example_description/models/phantomx/meshes/connect_coll.STL" scale="1 1 1"/>
      </geometry>
    </collision>
  </link>
  <link name="femur_lm">
    <inertial>
      <!-- <origin xyz="0 0 0" rpy="0 0 0"  /> -->
      <mass value="0.1"/>
      <!-- <inertia ixx="0.0051411124"  ixy="0"  ixz="0" iyy="0.0081915737" iyz="0" izz="0.0011379812" /> -->
      <!-- <inertia ixx="7.74*1e-4" ixy="0.0" ixz="0.0" iyy="3.52*1e-5" iyz="0.0" izz="8.39*1e-5"/> -->
      <inertia ixx="0.01" ixy="0.0" ixz="0.0" iyy="0.01" iyz="0.0" izz="0.01"/>
    </inertial>
    <visual>
      <origin rpy="0 0 0" xyz="0 0 0"/>
      <geometry>
        <!--box size="0.045 0.022 0.0325" /-->
        <mesh filename="package://ros_gz_example_description/models/phantomx/meshes/thigh_l.STL" scale="1 1 1"/>
      </geometry>
      <material name="Grey">
        <color rgba="0.20 0.20 0.20 1.0"/>
      </material>
    </visual>
    <collision>
      <origin rpy="0 0 0" xyz="0 0 0"/>
      <geometry>
        <mesh filename="package://ros_gz_example_description/models/phantomx/thigh_l_coll.STL" scale="1 1 1"/>
      </geometry>
    </collision>
  </link>
  <link name="tibia_lm">
    <inertial>
      <!-- <origin xyz="0 0 0" rpy="0 0 0"  /> -->
      <mass value="0.1"/>
      <!-- <inertia ixx="0.0051411124"  ixy="-0.00057530255"  ixz="-0.000024729049" iyy="0.0081915737" iyz="-0.000019223094" izz="0.0011379812" /> -->
      <!-- <inertia ixx="2.96*1e-3" ixy="0.0" ixz="0.0" iyy="2.74*1e-4" iyz="0.0" izz="6*1e-5"/> -->
      <inertia ixx="0.01" ixy="0.0" ixz="0.0" iyy="0.01" iyz="0.0" izz="0.01"/>
    </inertial>
    <visual>
      <origin rpy="0 0 0" xyz="0 0 0"/>
      <geometry>
        <!--box size="0.045 0.022 0.0325" /-->
        <mesh filename="package://ros_gz_example_description/models/phantomx/meshes/tibia_l.STL" scale="1 1 1"/>
      </geometry>
      <material name="Grey">
        <color rgba="0.20 0.20 0.20 1.0"/>
      </material>
    </visual>
    <collision>
      <origin rpy="0 0 0" xyz="0 0 0"/>
      <geometry>
        <mesh filename="package://ros_gz_example_description/models/phantomx/meshes/tibia_l_coll.STL" scale="1 1 1"/>
      </geometry>
    </collision>
  </link>
  <joint name="j_coxa1_lm" type="revolute">
    <parent link="MP_BODY"/>
    <child link="coxa1_lm"/>
    <origin rpy="0 4.7123 3.14159" xyz="0 0.1034  0.001116"/>
    <axis xyz="1 0 0"/>
    <limit effort="2.8" lower="-2.6179939" upper="2.6179939" velocity="5.6548668"/>
  </joint>
  <joint name="j_coxa2_lm" type="fixed">
    <parent link="coxa1_lm"/>
    <child link="coxa2_lm"/>
    <origin rpy="0 1.5704 3.14159" xyz="0 -0.054 0"/>
  </joint>
  <joint name="j_femur_lm" type="revolute">
    <parent link="coxa2_lm"/>
    <child link="femur_lm"/>
    <origin rpy=" 0 3.14159 3.14159" xyz="0 0 0"/>
    <axis xyz="1 0 0"/>
    <limit effort="2.8" lower="-2.6179939" upper="2.6179939" velocity="5.6548668"/>
  </joint>
  <joint name="j_tibia_lm" type="revolute">
    <parent link="femur_lm"/>
    <child link="tibia_lm"/>
    <origin rpy="-1.5707 0 3.14159" xyz="0 -0.0645 -0.0145"/>
    <axis xyz="1 0 0"/>
    <limit effort="2.8" lower="-2.6179939" upper="2.6179939" velocity="5.6548668"/>
  </joint>
  <transmission name="t_coxa1_lm">
    <type>transmission_interface/SimpleTransmission</type>
    <joint name="j_coxa1_lm">
      <hardwareInterface>EffortJointInterface</hardwareInterface>
    </joint>
    <actuator name="m_coxa1_lm">
      <hardwareInterface>EffortJointInterface</hardwareInterface>
      <mechanicalReduction>1</mechanicalReduction>
    </actuator>
  </transmission>
  <transmission name="t_femur_lm">
    <type>transmission_interface/SimpleTransmission</type>
    <joint name="j_femur_lm">
      <hardwareInterface>EffortJointInterface</hardwareInterface>
    </joint>
    <actuator name="m_femur_lm">
      <hardwareInterface>EffortJointInterface</hardwareInterface>
      <mechanicalReduction>1</mechanicalReduction>
    </actuator>
  </transmission>
  <transmission name="t_tibia_lm">
    <type>transmission_interface/SimpleTransmission</type>
    <joint name="j_tibia_lm">
      <hardwareInterface>EffortJointInterface</hardwareInterface>
    </joint>
    <actuator name="m_tibia_lm">
      <hardwareInterface>EffortJointInterface</hardwareInterface>
      <mechanicalReduction>1</mechanicalReduction>
    </actuator>
  </transmission>
  <gazebo reference="coxa1_lm">
    <material>Gazebo/Gray</material>
  </gazebo>
  <gazebo reference="coxa2_lm">
    <material>Gazebo/Gray</material>
  </gazebo>
  <gazebo reference="femur_lm">
    <material>Gazebo/Gray</material>
  </gazebo>
  <gazebo reference="femur_lm">
    <material>Gazebo/Gray</material>
  </gazebo>
  <link name="coxa1_lr">
    <inertial>
      <origin rpy="0 0 0" xyz="0 -0.02633 0"/>
      <mass value="0.04"/>
      <!-- <inertia ixx="0.0051411124"  ixy="-0.00057530255"  ixz="-0.000024729049" iyy="0.0081915737" iyz="-0.000019223094" izz="0.0011379812" /> -->
      <inertia ixx="1e-3" ixy="0.0" ixz="0.0" iyy="1e-3" iyz="0.0" izz="1e-3"/>
    </inertial>
    <visual>
      <origin rpy="0 0 0" xyz="0 -0.0252 0"/>
      <geometry>
        <!--box size="0.045 0.022 0.0325" /-->
        <mesh filename="package://ros_gz_example_description/models/phantomx/meshes/connect.STL" scale="1 1 1"/>
      </geometry>
      <material name="Grey">
        <color rgba="0.20 0.20 0.20 1.0"/>
      </material>
    </visual>
    <collision>
      <origin rpy="0 0 0" xyz="0 -0.02633 0"/>
      <geometry>
        <mesh filename="package://ros_gz_example_description/models/phantomx/meshes/connect_coll.STL" scale="1 1 1"/>
      </geometry>
    </collision>
  </link>
  <link name="coxa2_lr">
    <inertial>
      <origin rpy="0 0 0" xyz="0 -0.02633 0"/>
      <mass value="0.04"/>
      <!-- <inertia ixx="0.0051411124"  ixy="-0.00057530255"  ixz="-0.000024729049" iyy="0.0081915737" iyz="-0.000019223094" izz="0.0011379812" /> -->
      <inertia ixx="1e-3" ixy="0.0" ixz="0.0" iyy="1e-3" iyz="0.0" izz="1e-3"/>
    </inertial>
    <visual>
      <origin rpy="0 0 0" xyz="0 -0.0252 0"/>
      <geometry>
        <!--box size="0.045 0.022 0.0325" /-->
        <mesh filename="package://ros_gz_example_description/models/phantomx/meshes/connect.STL" scale="1 1 1"/>
      </geometry>
      <material name="Grey">
        <color rgba="0.20 0.20 0.20 1.0"/>
      </material>
    </visual>
    <collision>
      <origin rpy="0 0 0" xyz="0 -0.02633 0"/>
      <geometry>
        <mesh filename="package://ros_gz_example_description/models/phantomx/meshes/connect_coll.STL" scale="1 1 1"/>
      </geometry>
    </collision>
  </link>
  <link name="femur_lr">
    <inertial>
      <!-- <origin xyz="0 0 0" rpy="0 0 0"  /> -->
      <mass value="0.1"/>
      <!-- <inertia ixx="0.0051411124"  ixy="0"  ixz="0" iyy="0.0081915737" iyz="0" izz="0.0011379812" /> -->
      <!-- <inertia ixx="7.74*1e-4" ixy="0.0" ixz="0.0" iyy="3.52*1e-5" iyz="0.0" izz="8.39*1e-5"/> -->
      <inertia ixx="0.01" ixy="0.0" ixz="0.0" iyy="0.01" iyz="0.0" izz="0.01"/>
    </inertial>
    <visual>
      <origin rpy="0 0 0" xyz="0 0 0"/>
      <geometry>
        <!--box size="0.045 0.022 0.0325" /-->
        <mesh filename="package://ros_gz_example_description/models/phantomx/meshes/thigh_l.STL" scale="1 1 1"/>
      </geometry>
      <material name="Grey">
        <color rgba="0.20 0.20 0.20 1.0"/>
      </material>
    </visual>
    <collision>
      <origin rpy="0 0 0" xyz="0 0 0"/>
      <geometry>
        <mesh filename="package://ros_gz_example_description/models/phantomx/thigh_l_coll.STL" scale="1 1 1"/>
      </geometry>
    </collision>
  </link>
  <link name="tibia_lr">
    <inertial>
      <!-- <origin xyz="0 0 0" rpy="0 0 0"  /> -->
      <mass value="0.1"/>
      <!-- <inertia ixx="0.0051411124"  ixy="-0.00057530255"  ixz="-0.000024729049" iyy="0.0081915737" iyz="-0.000019223094" izz="0.0011379812" /> -->
      <!-- <inertia ixx="2.96*1e-3" ixy="0.0" ixz="0.0" iyy="2.74*1e-4" iyz="0.0" izz="6*1e-5"/> -->
      <inertia ixx="0.01" ixy="0.0" ixz="0.0" iyy="0.01" iyz="0.0" izz="0.01"/>
    </inertial>
    <visual>
      <origin rpy="0 0 0" xyz="0 0 0"/>
      <geometry>
        <!--box size="0.045 0.022 0.0325" /-->
        <mesh filename="package://ros_gz_example_description/models/phantomx/meshes/tibia_l.STL" scale="1 1 1"/>
      </geometry>
      <material name="Grey">
        <color rgba="0.20 0.20 0.20 1.0"/>
      </material>
    </visual>
    <collision>
      <origin rpy="0 0 0" xyz="0 0 0"/>
      <geometry>
        <mesh filename="package://ros_gz_example_description/models/phantomx/meshes/tibia_l_coll.STL" scale="1 1 1"/>
      </geometry>
    </collision>
  </link>
  <joint name="j_coxa1_lr" type="revolute">
    <parent link="MP_BODY"/>
    <child link="coxa1_lr"/>
    <origin rpy="0 4.7123 3.9269908169872414" xyz="-0.1248 0.06164  0.001116"/>
    <axis xyz="1 0 0"/>
    <limit effort="2.8" lower="-2.6179939" upper="2.6179939" velocity="5.6548668"/>
  </joint>
  <joint name="j_coxa2_lr" type="fixed">
    <parent link="coxa1_lr"/>
    <child link="coxa2_lr"/>
    <origin rpy="0 1.5704 3.14159" xyz="0 -0.054 0"/>
  </joint>
  <joint name="j_femur_lr" type="revolute">
    <parent link="coxa2_lr"/>
    <child link="femur_lr"/>
    <origin rpy=" 0 3.14159 3.14159" xyz="0 0 0"/>
    <axis xyz="1 0 0"/>
    <limit effort="2.8" lower="-2.6179939" upper="2.6179939" velocity="5.6548668"/>
  </joint>
  <joint name="j_tibia_lr" type="revolute">
    <parent link="femur_lr"/>
    <child link="tibia_lr"/>
    <origin rpy="-1.5707 0 3.14159" xyz="0 -0.0645 -0.0145"/>
    <axis xyz="1 0 0"/>
    <limit effort="2.8" lower="-2.6179939" upper="2.6179939" velocity="5.6548668"/>
  </joint>
  <transmission name="t_coxa1_lr">
    <type>transmission_interface/SimpleTransmission</type>
    <joint name="j_coxa1_lr">
      <hardwareInterface>EffortJointInterface</hardwareInterface>
    </joint>
    <actuator name="m_coxa1_lr">
      <hardwareInterface>EffortJointInterface</hardwareInterface>
      <mechanicalReduction>1</mechanicalReduction>
    </actuator>
  </transmission>
  <transmission name="t_femur_lr">
    <type>transmission_interface/SimpleTransmission</type>
    <joint name="j_femur_lr">
      <hardwareInterface>EffortJointInterface</hardwareInterface>
    </joint>
    <actuator name="m_femur_lr">
      <hardwareInterface>EffortJointInterface</hardwareInterface>
      <mechanicalReduction>1</mechanicalReduction>
    </actuator>
  </transmission>
  <transmission name="t_tibia_lr">
    <type>transmission_interface/SimpleTransmission</type>
    <joint name="j_tibia_lr">
      <hardwareInterface>EffortJointInterface</hardwareInterface>
    </joint>
    <actuator name="m_tibia_lr">
      <hardwareInterface>EffortJointInterface</hardwareInterface>
      <mechanicalReduction>1</mechanicalReduction>
    </actuator>
  </transmission>
  <gazebo reference="coxa1_lr">
    <material>Gazebo/Gray</material>
  </gazebo>
  <gazebo reference="coxa2_lr">
    <material>Gazebo/Gray</material>
  </gazebo>
  <gazebo reference="femur_lr">
    <material>Gazebo/Gray</material>
  </gazebo>
  <gazebo reference="femur_lr">
    <material>Gazebo/Gray</material>
  </gazebo>
  <gazebo>
    <plugin filename="libgazebo_ros_control.so" name="gazebo_ros_control">
      <robotNamespace>/phantomx</robotNamespace>
    </plugin>
  </gazebo>
</robot>
