<?xml version="1.0" ?>
<robot xmlns:xacro="http://www.ros.org/wiki/xacro">

<xacro:property name="connect_offset" value="0.02633" />
<xacro:property name="femur_offset_y" value="-0.0645" />
<xacro:property name="femur_offset_z" value="-0.0145" />



<xacro:macro name="phantomx" params="parent *origin">


      <joint name="j_phantomx_attachment" type="fixed">
        <parent link="${parent}"/>
        <child link="MP_BODY"/>
        <insert_block name="origin" />
      </joint>
      

      <link name="MP_BODY">
        <inertial>
          <!-- <origin xyz="0 0 0" /> -->
          <mass value="0.97559947"/>
          <inertia ixx="3.1081800"  ixy="-0.25460189"  ixz="2.0318174" iyy="6.3787776" iyz="0.16417863" izz="5.3316425" />
        </inertial>
        <visual>
          <!--origin xyz="-0.0235 0 -0.03525" rpy="0 0 0" /-->
          <origin xyz="0 0 0" rpy="0 0 0" />
          <geometry>
            <!--box size="0.102 0.109 0.106" /-->
            <mesh filename="package://ros_gz_example_description/models/phantomx/meshes/body.STL"  scale="1 1 1"/>
          </geometry>
          <material name="Grey">
            <color rgba="0.20 0.20 0.20 1.0"/>
          </material>
        </visual>
        <collision>
          <origin xyz="0 0 0" rpy="0 0 0" />
          <geometry>
            <mesh filename="package://ros_gz_example_description/models/phantomx/meshes/body_coll.STL"  scale="1 1 1"/>
          </geometry>

        </collision>
      </link>


      <gazebo reference="MP_BODY">    
        <material>Gazebo/Grey</material>
      </gazebo>


    <xacro:leg_l xyz="0.1248 -0.06164  0.001116"  rpy="0 4.7123 0.7853981633974483" suffix="rf"/>
    <xacro:leg_l xyz="0 -0.1034  0.001116"  rpy="0 4.7123 0" suffix="rm"/>
    <xacro:leg_l xyz="-0.1248 -0.06164  0.001116"  rpy="0 4.7123 -0.7853981633974483" suffix="rr"/>


    <xacro:leg_l xyz="0.1248 0.06164  0.001116"  rpy="0 4.7123 2.356194490192345" suffix="lf"/>
    <xacro:leg_l xyz="0 0.1034  0.001116"  rpy="0 4.7123 3.14159" suffix="lm"/>
    <xacro:leg_l xyz="-0.1248 0.06164  0.001116"  rpy="0 4.7123 3.9269908169872414" suffix="lr"/>

</xacro:macro>





 <xacro:macro name="leg_l" params="xyz rpy suffix">



  <link name="coxa1_${suffix}">
    <inertial>
      <origin xyz="0 -${connect_offset} 0" rpy="0 0 0"  />
      <mass value="0.04"/>
     <!-- <inertia ixx="0.0051411124"  ixy="-0.00057530255"  ixz="-0.000024729049" iyy="0.0081915737" iyz="-0.000019223094" izz="0.0011379812" /> -->
     <inertia ixx="1e-3" ixy="0.0" ixz="0.0" iyy="1e-3" iyz="0.0" izz="1e-3"/>
    </inertial>
    <visual>
      <origin xyz="0 -0.0252 0" rpy="0 0 0"  />
      <geometry>
        <!--box size="0.045 0.022 0.0325" /-->
        <mesh filename="package://ros_gz_example_description/models/phantomx/meshes/connect.STL"  scale="1 1 1"/>
      </geometry>
      <material name="Grey">
        <color rgba="0.20 0.20 0.20 1.0"/>
      </material>
    </visual>
    <collision>
      <origin xyz="0 -${connect_offset} 0" rpy="0 0 0"  />
      <geometry>
        <mesh filename="package://ros_gz_example_description/models/phantomx/meshes/connect_coll.STL"  scale="1 1 1"/>
      </geometry>
    </collision>
  </link>


  <link name="coxa2_${suffix}">
    <inertial>
      <origin xyz="0 -${connect_offset} 0" rpy="0 0 0"  />
      <mass value="0.04"/>
      <!-- <inertia ixx="0.0051411124"  ixy="-0.00057530255"  ixz="-0.000024729049" iyy="0.0081915737" iyz="-0.000019223094" izz="0.0011379812" /> -->
      <inertia ixx="1e-3" ixy="0.0" ixz="0.0" iyy="1e-3" iyz="0.0" izz="1e-3"/>
    </inertial>
    <visual>
      <origin xyz="0 -0.0252 0" rpy="0 0 0"  />
      <geometry>
        <!--box size="0.045 0.022 0.0325" /-->
        <mesh filename="package://ros_gz_example_description/models/phantomx/meshes/connect.STL"  scale="1 1 1"/>
      </geometry>
      <material name="Grey">
        <color rgba="0.20 0.20 0.20 1.0"/>
      </material>
    </visual>
    <collision>
      <origin xyz="0 -${connect_offset} 0" rpy="0 0 0"  />
      <geometry>
        <mesh filename="package://ros_gz_example_description/models/phantomx/meshes/connect_coll.STL"  scale="1 1 1"/>
      </geometry>
    </collision>
  </link>



  <link name="femur_${suffix}">
    <inertial>
      <!-- <origin xyz="0 0 0" rpy="0 0 0"  /> -->
      <mass value="0.1"/>
      <!-- <inertia ixx="0.0051411124"  ixy="0"  ixz="0" iyy="0.0081915737" iyz="0" izz="0.0011379812" /> -->
      <!-- <inertia ixx="7.74*1e-4" ixy="0.0" ixz="0.0" iyy="3.52*1e-5" iyz="0.0" izz="8.39*1e-5"/> -->
      <inertia ixx="0.01" ixy="0.0" ixz="0.0" iyy="0.01" iyz="0.0" izz="0.01"/>
    </inertial>
    <visual>
      <origin xyz="0 0 0" rpy="0 0 0"  />
      <geometry>
        <!--box size="0.045 0.022 0.0325" /-->
        <mesh filename="package://ros_gz_example_description/models/phantomx/meshes/thigh_l.STL"  scale="1 1 1"/>
      </geometry>
      <material name="Grey">
        <color rgba="0.20 0.20 0.20 1.0"/>
      </material>
    </visual>
    <collision>
      <origin xyz="0 0 0" rpy="0 0 0"  />
      <geometry>
        <mesh filename="package://ros_gz_example_description/models/phantomx/thigh_l_coll.STL"  scale="1 1 1"/>
      </geometry>
    </collision>
  </link>



  <link name="tibia_${suffix}">
    <inertial>
      <!-- <origin xyz="0 0 0" rpy="0 0 0"  /> -->
      <mass value="0.1"/>
      <!-- <inertia ixx="0.0051411124"  ixy="-0.00057530255"  ixz="-0.000024729049" iyy="0.0081915737" iyz="-0.000019223094" izz="0.0011379812" /> -->
      <!-- <inertia ixx="2.96*1e-3" ixy="0.0" ixz="0.0" iyy="2.74*1e-4" iyz="0.0" izz="6*1e-5"/> -->
      <inertia ixx="0.01" ixy="0.0" ixz="0.0" iyy="0.01" iyz="0.0" izz="0.01"/>
    </inertial>
    <visual>
      <origin xyz="0 0 0" rpy="0 0 0"  />
      <geometry>
        <!--box size="0.045 0.022 0.0325" /-->
        <mesh filename="package://ros_gz_example_description/models/phantomx/meshes/tibia_l.STL"  scale="1 1 1"/>
      </geometry>
      <material name="Grey">
        <color rgba="0.20 0.20 0.20 1.0"/>
      </material>
    </visual>
    <collision>
      <origin xyz="0 0 0" rpy="0 0 0"  />
      <geometry>
        <mesh filename="package://ros_gz_example_description/models/phantomx/meshes/tibia_l_coll.STL"  scale="1 1 1"/>
      </geometry>
    </collision>
  </link>



  <joint name="j_coxa1_${suffix}" type="revolute">
    <parent link="MP_BODY"/>
    <child link="coxa1_${suffix}"/>
    <origin xyz="${xyz}" rpy="${rpy}" />
    <axis xyz="1 0 0" />
    <limit effort="2.8" velocity="5.6548668" lower="-2.6179939" upper="2.6179939" />
  </joint>

  <joint name="j_coxa2_${suffix}" type="fixed">
    <parent link="coxa1_${suffix}"/>
    <child link="coxa2_${suffix}"/>
    <origin xyz="0 -0.054 0" rpy="0 1.5704 3.14159" />
  </joint>


  <joint name="j_femur_${suffix}" type="revolute">
    <parent link="coxa2_${suffix}"/>
    <child link="femur_${suffix}"/>
    <origin xyz="0 0 0" rpy=" 0 3.14159 3.14159" />
    <axis xyz="1 0 0" />
    <limit effort="2.8" velocity="5.6548668" lower="-2.6179939" upper="2.6179939" />
  </joint>

  <joint name="j_tibia_${suffix}" type="revolute">
    <parent link="femur_${suffix}"/>
    <child link="tibia_${suffix}"/>
    <origin xyz="0 ${femur_offset_y} ${femur_offset_z}" rpy="-1.5707 0 3.14159" />
    <axis xyz="1 0 0" />
    <limit effort="2.8" velocity="5.6548668" lower="-2.6179939" upper="2.6179939" />
  </joint>



   <transmission name="t_coxa1_${suffix}">
    <type>transmission_interface/SimpleTransmission</type>
    <joint name="j_coxa1_${suffix}">
      <hardwareInterface>EffortJointInterface</hardwareInterface>    
    </joint>
    <actuator name="m_coxa1_${suffix}">
      <hardwareInterface>EffortJointInterface</hardwareInterface>
      <mechanicalReduction>1</mechanicalReduction>
    </actuator>
  </transmission>


   <transmission name="t_femur_${suffix}">
    <type>transmission_interface/SimpleTransmission</type>
    <joint name="j_femur_${suffix}">
      <hardwareInterface>EffortJointInterface</hardwareInterface>    
    </joint>
    <actuator name="m_femur_${suffix}">
      <hardwareInterface>EffortJointInterface</hardwareInterface>
      <mechanicalReduction>1</mechanicalReduction>
    </actuator>
  </transmission>


   <transmission name="t_tibia_${suffix}">
    <type>transmission_interface/SimpleTransmission</type>
    <joint name="j_tibia_${suffix}">
      <hardwareInterface>EffortJointInterface</hardwareInterface>
    </joint>
    <actuator name="m_tibia_${suffix}">
      <hardwareInterface>EffortJointInterface</hardwareInterface>
      <mechanicalReduction>1</mechanicalReduction>
    </actuator>
  </transmission>



  <gazebo reference="coxa1_${suffix}">    
    <material>Gazebo/Gray</material>
  </gazebo>

  <gazebo reference="coxa2_${suffix}">    
    <material>Gazebo/Gray</material>
  </gazebo>

  <gazebo reference="femur_${suffix}">    
    <material>Gazebo/Gray</material>
  </gazebo>

  <gazebo reference="femur_${suffix}">    
    <material>Gazebo/Gray</material>
  </gazebo>

  
</xacro:macro>





</robot>
